Workbook

Sheet README
A1: O2I fixture workbook
A2: Workshop AI-Driven SDLC with Databricks. Kit version 2.0. All data is fictional.
A4: What this is | B4: The fixture is the small, hand-verifiable part of the training data: 56 delivered invoice lines in 48 named cases, 11 customer rows, 9 product rows, 42 order lines, and the expected outcome of every delivered row for both versions of the business contract. Each case exercises one rule or one edge of the contract.
A5: Why it matters | B5: An expected result is only worth something when it does not come from the code under test. Every expected value in this workbook comes from the business contract, or from a calculation that you can follow cell by cell.
A6: Where else it lives | B6: The same content is in Unity Catalog as the tables o2i.fixture_* and in the project as tests/fixtures/*.csv. The code tests and the data-quality checks compare your results with it.
A7: Lab 1 | B7: Sheet cases: the cases that the first transformation must get right are the ones decided by rules R2, R5, and R6.
A8: Lab 3 | B8: Sheet tax_and_gross: the rows marked 'tie' give you the numbers for the two code tests that you write. Sheet net_amount_rule: rule R7 for every row, with signs.
A9: Lab 4 | B9: Sheet cases: F36 to F42 are the acceptance cases of rule R8. Column G shows which cases change with contract 1.1.
A10: Colors | B10: Blue: a delivered value, or a value written by hand from the contract. Black: a formula. An empty cell in a delivered column is a missing value (NULL).
A11: Arithmetic | B11: The calculations use whole numbers (cents, thousandths of a quantity, ten-thousandths of a price or rate) until the last division, so no result depends on binary floating point. ROUND in a spreadsheet rounds half away from zero. That is the 'half up' of the contract: 0.165 becomes 0.17, and -0.165 becomes -0.17.
A12: Rule | B12: Never change an expected value to make a test or a check pass. If you think that an expected value is wrong, say why, and ask the owner of the contract.
A14: Sheets
A15: cases | B15: The 48 cases: what each one tests, its delivered rows, and the expected outcome under contract 1.0 and 1.1.
A16: rows | B16: The 56 delivered invoice lines with every column, the case, and the expected outcome. The status is shown with its spaces.
A17: summary | B17: Rows by outcome, counted from the sheet rows with formulas.
A18: net_amount_rule | B18: Rule R7 by hand for every row: Quantity x UnitPrice, rounded half up, compared with the delivered NetAmount.
A19: tax_and_gross | B19: TaxAmount and GrossAmount by hand for the 22 lines that contract 1.0 accepts, and what half-even rounding would give.
A20: customers | B20: Fixture customer master: 11 rows. One key has two rows.
A21: products | B21: Fixture product master: 9 rows. One key has two rows.
A22: orders | B22: Fixture order lines: 42 rows. One order line exists twice.
A23: expected_results | B23: The expected outcome of every row for each contract version, as in the table o2i.fixture_expected_results.

Sheet cases
A1: CaseID | B1: What the case tests | C1: Decided by (1.0) | D1: Decided by (1.1) | E1: Delivered rows | F1: Expected under contract 1.0 | G1: Expected under contract 1.1 | H1: Changes with 1.1
A2: F01 | B2: Posted invoice line, standard tax rate | C2: passes R1 to R7 | D2: passes R1 to R8 | E2: F0001 | F2: ACCEPTED | G2: ACCEPTED | H2: =IF(F2=G2,"","changes")
A3: F02 | B3: Fractional quantity: 2.5 h x 12.25 = 30.625, rounds half up to 30.63 | C3: passes R1 to R7 | D3: passes R1 to R8 | E3: F0002 | F3: ACCEPTED | G3: ACCEPTED | H3: =IF(F3=G3,"","changes")
A4: F03 | B4: TaxRate is NULL: no tax applies, gross equals net | C4: passes R1 to R7 | D4: passes R1 to R8 | E4: F0003 | F4: ACCEPTED | G4: ACCEPTED | H4: =IF(F4=G4,"","changes")
A5: F04 | B5: Tax tie: 3.00 x 0.055 = 0.165, rounds half up to 0.17 | C5: passes R1 to R7 | D5: passes R1 to R8 | E5: F0004 | F5: ACCEPTED | G5: ACCEPTED | H5: =IF(F5=G5,"","changes")
A6: F05 | B6: Valid credit note line: negative quantity and negative amounts | C6: passes R1 to R7 | D6: passes R1 to R8 | E6: F0005 | F6: ACCEPTED | G6: ACCEPTED | H6: =IF(F6=G6,"","changes")
A7: F06 | B7: Credit with a tax tie: -3.00 x 0.055 = -0.165, rounds half up to -0.17 | C7: passes R1 to R7 | D7: passes R1 to R8 | E7: F0006 | F7: ACCEPTED | G7: ACCEPTED | H7: =IF(F7=G7,"","changes")
A8: F07 | B8: Status 'Posted ' (mixed case, trailing space) is a posted line | C8: passes R1 to R7 | D8: passes R1 to R8 | E8: F0007 | F8: ACCEPTED | G8: ACCEPTED | H8: =IF(F8=G8,"","changes")
A9: F08 | B9: Status ' posted' (leading space, lower case); tax tie 0.50 x 0.21 = 0.105 | C9: passes R1 to R7 | D9: passes R1 to R8 | E9: F0008 | F9: ACCEPTED | G9: ACCEPTED | H9: =IF(F9=G9,"","changes")
A10: F09 | B10: Draft invoice | C10: R2 | D10: R2 | E10: F0009 | F10: EXCLUDED NOT_POSTED | G10: EXCLUDED NOT_POSTED | H10: =IF(F10=G10,"","changes")
A11: F10 | B11: Status 'Cancelled' (mixed case) | C11: R2 | D11: R2 | E11: F0010 | F11: EXCLUDED NOT_POSTED | G11: EXCLUDED NOT_POSTED | H11: =IF(F11=G11,"","changes")
A12: F11 | B12: Status 'PENDING' is not an allowed value | C12: R2 | D12: R2 | E12: F0011 | F12: QUARANTINED UNEXPECTED_STATUS | G12: QUARANTINED UNEXPECTED_STATUS | H12: =IF(F12=G12,"","changes")
A13: F12 | B13: CustomerID is NULL | C13: R1 | D13: R1 | E13: F0012 | F13: QUARANTINED MISSING_REQUIRED_FIELD | G13: QUARANTINED MISSING_REQUIRED_FIELD | H13: =IF(F13=G13,"","changes")
... A49: F48 | B49: Cancelled invoice | C49: R2 | D49: R2 | E49: F0048 | F49: EXCLUDED NOT_POSTED | G49: EXCLUDED NOT_POSTED | H49: =IF(F49=G49,"","changes")
A51: Cases | B51: =COUNTA(A2:A49) -> 48
A52: Change | B52: =COUNTIF(H2:H49,"changes") -> 5 | C52: cases get another outcome with contract 1.1 (rule R8)

Sheet rows
A1: RawRowID | B1: CaseID | C1: InvoiceID | D1: LineNumber | E1: InvoiceDate | F1: DocumentType | G1: Status | H1: Status, spaces visible | I1: CustomerID | J1: ProductID | K1: OrderID | L1: OrderLineNumber | M1: Quantity | N1: UnitPrice | O1: NetAmount | P1: TaxRate | Q1: Currency | R1: SalesOrg | S1: SourceSystem | T1: LoadBatchID | U1: IngestedAt | V1: Expected 1.0 | W1: Reason 1.0 | X1: Expected 1.1 | Y1: Reason 1.1
A2: F0001 | B2: F01 | C2: INV-3000001 | D2: 1 | E2: 2026-04-02 | F2: INVOICE | G2: POSTED | H2: ="["&G2&"]" -> [POSTED] | I2: C200001 | J2: P-20001 | K2: SO-3000001 | L2: 1 | M2: 4 | N2: 91.7875 | O2: 367.15 | P2: 0.2 | Q2: EUR | R2: FR10 | S2: ERP_EU | T2: LB-20260403 | U2: 2026-04-03 02:10:00 | V2: ACCEPTED | X2: ACCEPTED
A3: F0002 | B3: F02 | C3: INV-3000001 | D3: 2 | E3: 2026-04-02 | F3: INVOICE | G3: POSTED | H3: ="["&G3&"]" -> [POSTED] | I3: C200001 | J3: P-20003 | K3: SO-3000001 | L3: 2 | M3: 2.5 | N3: 12.25 | O3: 30.63 | P3: 0.2 | Q3: EUR | R3: FR10 | S3: ERP_EU | T3: LB-20260403 | U3: 2026-04-03 02:10:00 | V3: ACCEPTED | X3: ACCEPTED
A4: F0003 | B4: F03 | C4: INV-3000002 | D4: 1 | E4: 2026-04-02 | F4: INVOICE | G4: POSTED | H4: ="["&G4&"]" -> [POSTED] | I4: C200004 | J4: P-20001 | K4: SO-3000002 | L4: 1 | M4: 8 | N4: 99.1305 | O4: 793.04 | Q4: USD | R4: US10 | S4: ERP_NA | T4: LB-20260403 | U4: 2026-04-03 02:10:00 | V4: ACCEPTED | X4: ACCEPTED
A5: F0004 | B5: F04 | C5: INV-3000003 | D5: 1 | E5: 2026-04-02 | F5: INVOICE | G5: POSTED | H5: ="["&G5&"]" -> [POSTED] | I5: C200010 | J5: P-20004 | K5: SO-3000003 | L5: 1 | M5: 1 | N5: 3 | O5: 3 | P5: 0.055 | Q5: EUR | R5: FR10 | S5: ERP_EU | T5: LB-20260403 | U5: 2026-04-03 02:10:00 | V5: ACCEPTED | X5: ACCEPTED
A6: F0005 | B6: F05 | C6: CN-3000004 | D6: 1 | E6: 2026-04-03 | F6: CREDIT_NOTE | G6: POSTED | H6: ="["&G6&"]" -> [POSTED] | I6: C200001 | J6: P-20001 | K6: SO-3000001 | L6: 1 | M6: -4 | N6: 91.7875 | O6: -367.15 | P6: 0.2 | Q6: EUR | R6: FR10 | S6: ERP_EU | T6: LB-20260403 | U6: 2026-04-03 02:10:00 | V6: ACCEPTED | X6: ACCEPTED
A7: F0006 | B7: F06 | C7: CN-3000005 | D7: 1 | E7: 2026-04-03 | F7: CREDIT_NOTE | G7: POSTED | H7: ="["&G7&"]" -> [POSTED] | I7: C200010 | J7: P-20004 | K7: SO-3000003 | L7: 1 | M7: -1 | N7: 3 | O7: -3 | P7: 0.055 | Q7: EUR | R7: FR10 | S7: ERP_EU | T7: LB-20260403 | U7: 2026-04-03 02:10:00 | V7: ACCEPTED | X7: ACCEPTED
A8: F0007 | B8: F07 | C8: INV-3000006 | D8: 1 | E8: 2026-04-02 | F8: INVOICE | G8: Posted | H8: ="["&G8&"]" -> [Posted ] | I8: C200002 | J8: P-20002 | K8: SO-3000004 | L8: 1 | M8: 6 | N8: 416.075 | O8: 2496.45 | P8: 0.19 | Q8: EUR | R8: DE10 | S8: ERP_EU | T8: LB-20260403 | U8: 2026-04-03 02:10:00 | V8: ACCEPTED | X8: ACCEPTED
A9: F0008 | B9: F08 | C9: INV-3000007 | D9: 1 | E9: 2026-04-02 | F9: INVOICE | G9: posted | H9: ="["&G9&"]" -> [ posted] | I9: C200006 | J9: P-20005 | K9: SO-3000005 | L9: 1 | M9: 1 | N9: 0.5 | O9: 0.5 | P9: 0.21 | Q9: EUR | R9: ES10 | S9: ERP_EU | T9: LB-20260403 | U9: 2026-04-03 02:10:00 | V9: ACCEPTED | X9: ACCEPTED
A10: F0009 | B10: F09 | C10: INV-3000008 | D10: 1 | E10: 2026-04-02 | F10: INVOICE | G10: DRAFT | H10: ="["&G10&"]" -> [DRAFT] | I10: C200001 | J10: P-20001 | K10: SO-3000006 | L10: 1 | M10: 4 | N10: 91.7875 | O10: 367.15 | P10: 0.2 | Q10: EUR | R10: FR10 | S10: ERP_EU | T10: LB-20260403 | U10: 2026-04-03 02:10:00 | V10: EXCLUDED | W10: NOT_POSTED | X10: EXCLUDED | Y10: NOT_POSTED
A11: F0010 | B11: F10 | C11: INV-3000009 | D11: 1 | E11: 2026-04-02 | F11: INVOICE | G11: Cancelled | H11: ="["&G11&"]" -> [Cancelled] | I11: C200002 | J11: P-20002 | K11: SO-3000006 | L11: 2 | M11: 2 | N11: 416.075 | O11: 832.15 | P11: 0.19 | Q11: EUR | R11: DE10 | S11: ERP_EU | T11: LB-20260403 | U11: 2026-04-03 02:10:00 | V11: EXCLUDED | W11: NOT_POSTED | X11: EXCLUDED | Y11: NOT_POSTED
A12: F0011 | B12: F11 | C12: INV-3000010 | D12: 1 | E12: 2026-04-02 | F12: INVOICE | G12: PENDING | H12: ="["&G12&"]" -> [PENDING] | I12: C200006 | J12: P-20001 | K12: SO-3000006 | L12: 3 | M12: 4 | N12: 96.508 | O12: 386.03 | P12: 0.21 | Q12: EUR | R12: ES10 | S12: ERP_EU | T12: LB-20260403 | U12: 2026-04-03 02:10:00 | V12: QUARANTINED | W12: UNEXPECTED_STATUS | X12: QUARANTINED | Y12: UNEXPECTED_STATUS
A13: F0012 | B13: F12 | C13: INV-3000011 | D13: 1 | E13: 2026-04-02 | F13: INVOICE | G13: POSTED | H13: ="["&G13&"]" -> [POSTED] | J13: P-20001 | K13: SO-3000007 | L13: 1 | M13: 4 | N13: 91.7875 | O13: 367.15 | P13: 0.2 | Q13: EUR | R13: FR10 | S13: ERP_EU | T13: LB-20260403 | U13: 2026-04-03 02:10:00 | V13: QUARANTINED | W13: MISSING_REQUIRED_FIELD | X13: QUARANTINED | Y13: MISSING_REQUIRED_FIELD
A14: F0013 | B14: F13 | C14: INV-3000012 | D14: 1 | E14: 2026-04-02 | F14: INVOICE | H14: ="["&G14&"]" -> [ ] | I14: C200001 | J14: P-20001 | K14: SO-3000007 | L14: 2 | M14: 2 | N14: 91.7875 | O14: 183.58 | P14: 0.2 | Q14: EUR | R14: FR10 | S14: ERP_EU | T14: LB-20260403 | U14: 2026-04-03 02:10:00 | V14: QUARANTINED | W14: MISSING_REQUIRED_FIELD | X14: QUARANTINED | Y14: MISSING_REQUIRED_FIELD
A15: F0014 | B15: F14 | C15: INV-3000013 | D15: 1 | E15: 2026-04-02 | F15: INVOICE | G15: POSTED | H15: ="["&G15&"]" -> [POSTED] | I15: C200002 | J15: P-20002 | K15: SO-3000007 | L15: 3 | M15: 2 | N15: 416.075 | P15: 0.19 | Q15: EUR | R15: DE10 | S15: ERP_EU | T15: LB-20260403 | U15: 2026-04-03 02:10:00 | V15: QUARANTINED | W15: MISSING_REQUIRED_FIELD | X15: QUARANTINED | Y15: MISSING_REQUIRED_FIELD
A16: F0015 | B16: F15 | C16: INV-3000014 | E16: 2026-04-02 | F16: INVOICE | G16: POSTED | H16: ="["&G16&"]" -> [POSTED] | I16: C200006 | J16: P-20005 | K16: SO-3000008 | L16: 1 | M16: 10 | N16: 0.465 | O16: 4.65 | P16: 0.21 | Q16: EUR | R16: ES10 | S16: ERP_EU | T16: LB-20260403 | U16: 2026-04-03 02:10:00 | V16: QUARANTINED | W16: MISSING_REQUIRED_FIELD | X16: QUARANTINED | Y16: MISSING_REQUIRED_FIELD
A17: F0016 | B17: F16 | C17: INV-3000015 | D17: 1 | E17: 2026-04-02 | F17: INVOICE | G17: DRAFT | H17: ="["&G17&"]" -> [DRAFT] | I17: C200001 | K17: SO-3000008 | L17: 2 | M17: 4 | N17: 91.7875 | O17: 367.15 | P17: 0.2 | Q17: EUR | R17: FR10 | S17: ERP_EU | T17: LB-20260403 | U17: 2026-04-03 02:10:00 | V17: QUARANTINED | W17: MISSING_REQUIRED_FIELD | X17: QUARANTINED | Y17: MISSING_REQUIRED_FIELD
A18: F0017 | B18: F17 | C18: INV-3000016 | D18: 1 | E18: 2026-04-02 | F18: INVOICE | G18: POSTED | H18: ="["&G18&"]" -> [POSTED] | I18: C200006 | J18: P-20001 | K18: SO-3000010 | L18: 1 | M18: 2 | N18: 96.508 | O18: 193.02 | P18: 0.21 | Q18: EUR | R18: ES10 | S18: ERP_EU | T18: LB-20260403 | U18: 2026-04-03 02:10:00 | V18: ACCEPTED | X18: ACCEPTED
A19: F0018 | B19: F18 | C19: INV-3000017 | D19: 1 | E19: 2026-04-02 | F19: INVOICE | G19: POSTED | H19: ="["&G19&"]" -> [POSTED] | I19: C200002 | J19: P-20005 | K19: SO-3000010 | L19: 2 | M19: 20 | N19: 0.465 | O19: 9.3 | P19: 0.19 | Q19: EUR | R19: DE10 | S19: ERP_EU | T19: LB-20260403 | U19: 2026-04-03 02:10:00 | V19: ACCEPTED | X19: ACCEPTED
A20: F0019 | B20: F19 | C20: INV-3000018 | D20: 1 | E20: 2026-04-02 | F20: INVOICE | G20: POSTED | H20: ="["&G20&"]" -> [POSTED] | I20: C200001 | J20: P-20001 | K20: SO-3000011 | L20: 1 | M20: 4 | N20: 91.7875 | O20: 367.15 | P20: 0.2 | Q20: EUR | R20: FR10 | S20: ERP_EU | T20: LB-20260403 | U20: 2026-04-03 02:10:00 | V20: QUARANTINED | W20: CONFLICTING_DUPLICATE | X20: QUARANTINED | Y20: CONFLICTING_DUPLICATE
A21: F0020 | B21: F20 | C21: INV-3000019 | D21: 1 | E21: 2026-04-02 | F21: INVOICE | G21: POSTED | H21: ="["&G21&"]" -> [POSTED] | I21: C200010 | J21: P-20002 | K21: SO-3000011 | L21: 2 | M21: 2 | N21: 430.76 | O21: 861.52 | P21: 0.2 | Q21: EUR | R21: FR10 | S21: ERP_EU | T21: LB-20260403 | U21: 2026-04-03 02:10:00 | V21: QUARANTINED | W21: CONFLICTING_DUPLICATE | X21: QUARANTINED | Y21: CONFLICTING_DUPLICATE
A22: F0021 | B22: F21 | C22: INV-3000020 | D22: 1 | E22: 2026-04-02 | F22: INVOICE | G22: DRAFT | H22: ="["&G22&"]" -> [DRAFT] | I22: C200001 | J22: P-20002 | K22: SO-3000012 | L22: 1 | M22: 2 | N22: 430.76 | O22: 861.52 | P22: 0.2 | Q22: EUR | R22: FR10 | S22: ERP_EU | T22: LB-20260403 | U22: 2026-04-03 02:10:00 | V22: EXCLUDED | W22: NOT_POSTED | X22: EXCLUDED | Y22: NOT_POSTED
A23: F0022 | B23: F22 | C23: INV-3000021 | D23: 1 | E23: 2026-04-02 | F23: INVOICE | G23: POSTED | H23: ="["&G23&"]" -> [POSTED] | I23: C299999 | J23: P-20001 | K23: SO-3000012 | L23: 2 | M23: 4 | N23: 91.7875 | O23: 367.15 | P23: 0.2 | Q23: EUR | R23: FR10 | S23: ERP_EU | T23: LB-20260403 | U23: 2026-04-03 02:10:00 | V23: QUARANTINED | W23: UNKNOWN_CUSTOMER | X23: QUARANTINED | Y23: UNKNOWN_CUSTOMER
A24: F0023 | B24: F23 | C24: INV-3000022 | D24: 1 | E24: 2026-02-30 | F24: INVOICE | G24: POSTED | H24: ="["&G24&"]" -> [POSTED] | I24: C200001 | J24: P-20001 | K24: SO-3000013 | L24: 1 | M24: 4 | N24: 91.7875 | O24: 367.15 | P24: 0.2 | Q24: EUR | R24: FR10 | S24: ERP_EU | T24: LB-20260403 | U24: 2026-04-03 02:10:00 | V24: QUARANTINED | W24: INVALID_DATE | X24: QUARANTINED | Y24: INVALID_DATE
A25: F0024 | B25: F24 | C25: INV-3000023 | D25: 1 | E25: 31/03/2026 | F25: INVOICE | G25: POSTED | H25: ="["&G25&"]" -> [POSTED] | I25: C200002 | J25: P-20002 | K25: SO-3000013 | L25: 2 | M25: 2 | N25: 416.075 | O25: 832.15 | P25: 0.19 | Q25: EUR | R25: DE10 | S25: ERP_EU | T25: LB-20260403 | U25: 2026-04-03 02:10:00 | V25: QUARANTINED | W25: INVALID_DATE | X25: QUARANTINED | Y25: INVALID_DATE
A26: F0025 | B26: F25 | C26: INV-3000024 | D26: 1 | E26: 2026-3-7 | F26: INVOICE | G26: POSTED | H26: ="["&G26&"]" -> [POSTED] | I26: C200006 | J26: P-20001 | K26: SO-3000013 | L26: 3 | M26: 4 | N26: 96.508 | O26: 386.03 | P26: 0.21 | Q26: EUR | R26: ES10 | S26: ERP_EU | T26: LB-20260403 | U26: 2026-04-03 02:10:00 | V26: QUARANTINED | W26: INVALID_DATE | X26: QUARANTINED | Y26: INVALID_DATE
A27: F0026 | B27: F26 | C27: INV-3000025 | D27: 1 | E27: 2026-04-02 | F27: INVOICE | G27: POSTED | H27: ="["&G27&"]" -> [POSTED] | I27: C299999 | J27: P-20002 | K27: SO-3000014 | L27: 1 | M27: 2 | N27: 430.76 | O27: 861.52 | P27: 0.2 | Q27: EUR | R27: FR10 | S27: ERP_EU | T27: LB-20260403 | U27: 2026-04-03 02:10:00 | V27: QUARANTINED | W27: UNKNOWN_CUSTOMER | X27: QUARANTINED | Y27: UNKNOWN_CUSTOMER
A28: F0027 | B28: F27 | C28: INV-3000026 | D28: 1 | E28: 2026-04-02 | F28: INVOICE | G28: POSTED | H28: ="["&G28&"]" -> [POSTED] | I28: C200007 | J28: P-20002 | K28: SO-3000014 | L28: 2 | M28: 4 | N28: 421 | O28: 1684 | P28: 0.21 | Q28: EUR | R28: BX10 | S28: ERP_EU | T28: LB-20260403 | U28: 2026-04-03 02:10:00 | V28: QUARANTINED | W28: AMBIGUOUS_CUSTOMER | X28: QUARANTINED | Y28: AMBIGUOUS_CUSTOMER
A29: F0028 | B29: F28 | C29: INV-3000027 | D29: 1 | E29: 2026-04-02 | F29: INVOICE | G29: POSTED | H29: ="["&G29&"]" -> [POSTED] | I29: c200001 | J29: P-20001 | K29: SO-3000014 | L29: 3 | M29: 4 | N29: 91.7875 | O29: 367.15 | P29: 0.2 | Q29: EUR | R29: FR10 | S29: ERP_EU | T29: LB-20260403 | U29: 2026-04-03 02:10:00 | V29: QUARANTINED | W29: UNKNOWN_CUSTOMER | X29: QUARANTINED | Y29: UNKNOWN_CUSTOMER
A30: F0029 | B30: F29 | C30: INV-3000028 | D30: 1 | E30: 2026-04-02 | F30: INVOICE | G30: POSTED | H30: ="["&G30&"]" -> [POSTED] | I30: C200001 | J30: P-29999 | K30: SO-3000015 | L30: 1 | M30: 4 | N30: 88 | O30: 352 | P30: 0.2 | Q30: EUR | R30: FR10 | S30: ERP_EU | T30: LB-20260403 | U30: 2026-04-03 02:10:00 | V30: QUARANTINED | W30: UNKNOWN_PRODUCT | X30: QUARANTINED | Y30: UNKNOWN_PRODUCT
A31: F0030 | B31: F30 | C31: INV-3000029 | D31: 1 | E31: 2026-04-02 | F31: INVOICE | G31: POSTED | H31: ="["&G31&"]" -> [POSTED] | I31: C200006 | J31: P-20006 | K31: SO-3000015 | L31: 2 | M31: 2 | N31: 127.88 | O31: 255.76 | P31: 0.21 | Q31: EUR | R31: ES10 | S31: ERP_EU | T31: LB-20260403 | U31: 2026-04-03 02:10:00 | V31: QUARANTINED | W31: AMBIGUOUS_PRODUCT | X31: QUARANTINED | Y31: AMBIGUOUS_PRODUCT
... A36: F0035 | B36: F35 | C36: INV-3000034 | D36: 1 | E36: 2026-04-02 | F36: INVOICE | G36: POSTED | H36: ="["&G36&"]" -> [POSTED] | I36: C200002 | J36: P-29999 | K36: SO-3000016 | L36: 3 | M36: 2 | N36: 88 | O36: 1760 | P36: 0.19 | Q36: EUR | R36: DE10 | S36: ERP_EU | T36: LB-20260403 | U36: 2026-04-03 02:10:00 | V36: QUARANTINED | W36: UNKNOWN_PRODUCT | X36: QUARANTINED | Y36: UNKNOWN_PRODUCT
A37: F0036 | B37: F36 | C37: INV-3000035 | D37: 1 | E37: 2026-04-02 | F37: INVOICE | G37: POSTED | H37: ="["&G37&"]" -> [POSTED] | I37: C200010 | J37: P-20008 | M37: 1.5 | N37: 29.99 | O37: 44.99 | Q37: EUR | R37: FR10 | S37: ERP_EU | T37: LB-20260403 | U37: 2026-04-03 02:10:00 | V37: ACCEPTED | X37: QUARANTINED | Y37: MISSING_ORDER_REF
A38: F0037 | B38: F37 | C38: INV-3000036 | D38: 1 | E38: 2026-04-02 | F38: INVOICE | G38: POSTED | H38: ="["&G38&"]" -> [POSTED] | I38: C200001 | J38: P-20001 | K38: SO-3000001 | L38: 9 | M38: 2 | N38: 91.7875 | O38: 183.58 | P38: 0.2 | Q38: EUR | R38: FR10 | S38: ERP_EU | T38: LB-20260403 | U38: 2026-04-03 02:10:00 | V38: ACCEPTED | X38: QUARANTINED | Y38: UNKNOWN_ORDER_REF
A39: F0038 | B39: F38 | C39: INV-3000037 | D39: 1 | E39: 2026-04-02 | F39: INVOICE | G39: POSTED | H39: ="["&G39&"]" -> [POSTED] | I39: C200006 | J39: P-20002 | K39: SO-3999999 | L39: 1 | M39: 4 | N39: 441 | O39: 1764 | P39: 0.21 | Q39: EUR | R39: ES10 | S39: ERP_EU | T39: LB-20260403 | U39: 2026-04-03 02:10:00 | V39: ACCEPTED | X39: QUARANTINED | Y39: UNKNOWN_ORDER_REF
A40: F0039 | B40: F39 | C40: INV-3000038 | D40: 1 | E40: 2026-04-02 | F40: INVOICE | G40: POSTED | H40: ="["&G40&"]" -> [POSTED] | I40: C200010 | J40: P-20001 | K40: SO-3000009 | L40: 1 | M40: 4 | N40: 93.361 | O40: 373.44 | P40: 0.2 | Q40: EUR | R40: FR10 | S40: ERP_EU | T40: LB-20260403 | U40: 2026-04-03 02:10:00 | V40: ACCEPTED | X40: QUARANTINED | Y40: AMBIGUOUS_ORDER_REF
A41: F0040 | B41: F40 | C41: CN-3000039 | D41: 1 | E41: 2026-04-03 | F41: CREDIT_NOTE | G41: POSTED | H41: ="["&G41&"]" -> [POSTED] | I41: C200002 | J41: P-20002 | K41: SO-3000004 | L41: 1 | M41: -2 | N41: 416.075 | O41: -832.15 | P41: 0.19 | Q41: EUR | R41: DE10 | S41: ERP_EU | T41: LB-20260403 | U41: 2026-04-03 02:10:00 | V41: ACCEPTED | X41: ACCEPTED
A42: F0041 | B42: F41 | C42: CN-3000040 | D42: 1 | E42: 2026-04-03 | F42: CREDIT_NOTE | G42: POSTED | H42: ="["&G42&"]" -> [POSTED] | I42: C200006 | J42: P-20002 | K42: SO-3999998 | L42: 1 | M42: -1 | N42: 441 | O42: -441 | P42: 0.21 | Q42: EUR | R42: ES10 | S42: ERP_EU | T42: LB-20260403 | U42: 2026-04-03 02:10:00 | V42: ACCEPTED | X42: QUARANTINED | Y42: UNKNOWN_ORDER_REF
A43: F0042 | B43: F42 | C43: INV-3000041 | D43: 1 | E43: 2026-04-02 | F43: INVOICE | G43: POSTED | H43: ="["&G43&"]" -> [POSTED] | I43: C200001 | J43: P-20001 | K43: SO-3999997 | L43: 1 | M43: 4 | N43: 91.7875 | O43: 376.15 | P43: 0.2 | Q43: EUR | R43: FR10 | S43: ERP_EU | T43: LB-20260403 | U43: 2026-04-03 02:10:00 | V43: QUARANTINED | W43: AMOUNT_MISMATCH | X43: QUARANTINED | Y43: AMOUNT_MISMATCH
A44: F0043 | B44: F43 | C44: INV-3000042 | D44: 1 | E44: 2026-04-02 | F44: INVOICE | G44: POSTED | H44: ="["&G44&"]" -> [POSTED] | I44: C200003 | J44: P-20007 | K44: SO-3000017 | L44: 1 | M44: 2 | N44: 1082.6196 | O44: 2165.24 | P44: 0.2 | Q44: GBP | R44: GB10 | S44: ERP_EU | T44: LB-20260403 | U44: 2026-04-03 02:10:00 | V44: ACCEPTED | X44: ACCEPTED
...

Sheet summary
A1: Disposition | B1: Reason code | C1: Rule | D1: Rows, contract 1.0 | E1: Rows, contract 1.1
A2: ACCEPTED | D2: =COUNTIF(rows!$V$2:$V$57,$A2) -> 22 | E2: =COUNTIF(rows!$X$2:$X$57,$A2) -> 17
A3: EXCLUDED | B3: NOT_POSTED | C3: R2 | D3: =COUNTIFS(rows!$V$2:$V$57,$A3,rows!$W$2:$W$57,$B3) -> 4 | E3: =COUNTIFS(rows!$X$2:$X$57,$A3,rows!$Y$2:$Y$57,$B3) -> 4
A4: EXCLUDED | B4: EXACT_REPLAY | C4: R3 | D4: =COUNTIFS(rows!$V$2:$V$57,$A4,rows!$W$2:$W$57,$B4) -> 4 | E4: =COUNTIFS(rows!$X$2:$X$57,$A4,rows!$Y$2:$Y$57,$B4) -> 4
A5: QUARANTINED | B5: MISSING_REQUIRED_FIELD | C5: R1 | D5: =COUNTIFS(rows!$V$2:$V$57,$A5,rows!$W$2:$W$57,$B5) -> 5 | E5: =COUNTIFS(rows!$X$2:$X$57,$A5,rows!$Y$2:$Y$57,$B5) -> 5
A6: QUARANTINED | B6: UNEXPECTED_STATUS | C6: R2 | D6: =COUNTIFS(rows!$V$2:$V$57,$A6,rows!$W$2:$W$57,$B6) -> 1 | E6: =COUNTIFS(rows!$X$2:$X$57,$A6,rows!$Y$2:$Y$57,$B6) -> 1
A7: QUARANTINED | B7: CONFLICTING_DUPLICATE | C7: R3 | D7: =COUNTIFS(rows!$V$2:$V$57,$A7,rows!$W$2:$W$57,$B7) -> 5 | E7: =COUNTIFS(rows!$X$2:$X$57,$A7,rows!$Y$2:$Y$57,$B7) -> 5
A8: QUARANTINED | B8: INVALID_DATE | C8: R4 | D8: =COUNTIFS(rows!$V$2:$V$57,$A8,rows!$W$2:$W$57,$B8) -> 4 | E8: =COUNTIFS(rows!$X$2:$X$57,$A8,rows!$Y$2:$Y$57,$B8) -> 4
A9: QUARANTINED | B9: UNKNOWN_CUSTOMER | C9: R5 | D9: =COUNTIFS(rows!$V$2:$V$57,$A9,rows!$W$2:$W$57,$B9) -> 4 | E9: =COUNTIFS(rows!$X$2:$X$57,$A9,rows!$Y$2:$Y$57,$B9) -> 4
A10: QUARANTINED | B10: AMBIGUOUS_CUSTOMER | C10: R5 | D10: =COUNTIFS(rows!$V$2:$V$57,$A10,rows!$W$2:$W$57,$B10) -> 1 | E10: =COUNTIFS(rows!$X$2:$X$57,$A10,rows!$Y$2:$Y$57,$B10) -> 1
A11: QUARANTINED | B11: UNKNOWN_PRODUCT | C11: R6 | D11: =COUNTIFS(rows!$V$2:$V$57,$A11,rows!$W$2:$W$57,$B11) -> 2 | E11: =COUNTIFS(rows!$X$2:$X$57,$A11,rows!$Y$2:$Y$57,$B11) -> 2
A12: QUARANTINED | B12: AMBIGUOUS_PRODUCT | C12: R6 | D12: =COUNTIFS(rows!$V$2:$V$57,$A12,rows!$W$2:$W$57,$B12) -> 1 | E12: =COUNTIFS(rows!$X$2:$X$57,$A12,rows!$Y$2:$Y$57,$B12) -> 1
A13: QUARANTINED | B13: AMOUNT_MISMATCH | C13: R7 | D13: =COUNTIFS(rows!$V$2:$V$57,$A13,rows!$W$2:$W$57,$B13) -> 3 | E13: =COUNTIFS(rows!$X$2:$X$57,$A13,rows!$Y$2:$Y$57,$B13) -> 3
A14: QUARANTINED | B14: MISSING_ORDER_REF | C14: R8 | D14: =COUNTIFS(rows!$V$2:$V$57,$A14,rows!$W$2:$W$57,$B14) -> 0 | E14: =COUNTIFS(rows!$X$2:$X$57,$A14,rows!$Y$2:$Y$57,$B14) -> 1
... A16: QUARANTINED | B16: AMBIGUOUS_ORDER_REF | C16: R8 | D16: =COUNTIFS(rows!$V$2:$V$57,$A16,rows!$W$2:$W$57,$B16) -> 0 | E16: =COUNTIFS(rows!$X$2:$X$57,$A16,rows!$Y$2:$Y$57,$B16) -> 1
A17: Total | D17: =SUM(D2:D16) -> 56 | E17: =SUM(E2:E16) -> 56
A18: Delivered rows | D18: =COUNTA(rows!$A$2:$A$57) -> 56 | E18: =COUNTA(rows!$A$2:$A$57) -> 56
A19: Reconciles | D19: =IF(D17=D18,"yes","NO") -> yes | E19: =IF(E17=E18,"yes","NO") -> yes
A21: Every delivered row has exactly one outcome: the total equals the number of delivered rows.

Sheet net_amount_rule
A1: RawRowID | B1: CaseID | C1: Quantity | D1: UnitPrice | E1: NetAmount as delivered | F1: Quantity in thousandths | G1: UnitPrice in ten-thousandths | H1: Quantity x UnitPrice in cents, exact | I1: Rounded half up, in cents | J1: NetAmount that rule R7 expects | K1: Rule R7 | L1: Expected outcome of the row, contract 1.0
A2: F0001 | B2: F01 | C2: 4 | D2: 91.7875 | E2: 367.15 | F2: =ROUND(C2*1000,0) -> 4000 | G2: =ROUND(D2*10000,0) -> 917875 | H2: =F2*G2/100000 -> 36715 | I2: =ROUND(H2,0) -> 36715 | J2: =I2/100 -> 367.15 | K2: =IF(OR(C2="",D2="",E2=""),"missing value",IF(ROUND(E2*100,0)=I2,"matches","MISMATCH")) -> matches | L2: ACCEPTED
A3: F0002 | B3: F02 | C3: 2.5 | D3: 12.25 | E3: 30.63 | F3: =ROUND(C3*1000,0) -> 2500 | G3: =ROUND(D3*10000,0) -> 122500 | H3: =F3*G3/100000 -> 3062.5 | I3: =ROUND(H3,0) -> 3063 | J3: =I3/100 -> 30.63 | K3: =IF(OR(C3="",D3="",E3=""),"missing value",IF(ROUND(E3*100,0)=I3,"matches","MISMATCH")) -> matches | L3: ACCEPTED
A4: F0003 | B4: F03 | C4: 8 | D4: 99.1305 | E4: 793.04 | F4: =ROUND(C4*1000,0) -> 8000 | G4: =ROUND(D4*10000,0) -> 991305 | H4: =F4*G4/100000 -> 79304.4 | I4: =ROUND(H4,0) -> 79304 | J4: =I4/100 -> 793.04 | K4: =IF(OR(C4="",D4="",E4=""),"missing value",IF(ROUND(E4*100,0)=I4,"matches","MISMATCH")) -> matches | L4: ACCEPTED
A5: F0004 | B5: F04 | C5: 1 | D5: 3 | E5: 3 | F5: =ROUND(C5*1000,0) -> 1000 | G5: =ROUND(D5*10000,0) -> 30000 | H5: =F5*G5/100000 -> 300 | I5: =ROUND(H5,0) -> 300 | J5: =I5/100 -> 3 | K5: =IF(OR(C5="",D5="",E5=""),"missing value",IF(ROUND(E5*100,0)=I5,"matches","MISMATCH")) -> matches | L5: ACCEPTED
A6: F0005 | B6: F05 | C6: -4 | D6: 91.7875 | E6: -367.15 | F6: =ROUND(C6*1000,0) -> -4000 | G6: =ROUND(D6*10000,0) -> 917875 | H6: =F6*G6/100000 -> -36715 | I6: =ROUND(H6,0) -> -36715 | J6: =I6/100 -> -367.15 | K6: =IF(OR(C6="",D6="",E6=""),"missing value",IF(ROUND(E6*100,0)=I6,"matches","MISMATCH")) -> matches | L6: ACCEPTED
A7: F0006 | B7: F06 | C7: -1 | D7: 3 | E7: -3 | F7: =ROUND(C7*1000,0) -> -1000 | G7: =ROUND(D7*10000,0) -> 30000 | H7: =F7*G7/100000 -> -300 | I7: =ROUND(H7,0) -> -300 | J7: =I7/100 -> -3 | K7: =IF(OR(C7="",D7="",E7=""),"missing value",IF(ROUND(E7*100,0)=I7,"matches","MISMATCH")) -> matches | L7: ACCEPTED
A8: F0007 | B8: F07 | C8: 6 | D8: 416.075 | E8: 2496.45 | F8: =ROUND(C8*1000,0) -> 6000 | G8: =ROUND(D8*10000,0) -> 4160750 | H8: =F8*G8/100000 -> 249645 | I8: =ROUND(H8,0) -> 249645 | J8: =I8/100 -> 2496.45 | K8: =IF(OR(C8="",D8="",E8=""),"missing value",IF(ROUND(E8*100,0)=I8,"matches","MISMATCH")) -> matches | L8: ACCEPTED
A9: F0008 | B9: F08 | C9: 1 | D9: 0.5 | E9: 0.5 | F9: =ROUND(C9*1000,0) -> 1000 | G9: =ROUND(D9*10000,0) -> 5000 | H9: =F9*G9/100000 -> 50 | I9: =ROUND(H9,0) -> 50 | J9: =I9/100 -> 0.5 | K9: =IF(OR(C9="",D9="",E9=""),"missing value",IF(ROUND(E9*100,0)=I9,"matches","MISMATCH")) -> matches | L9: ACCEPTED
A10: F0009 | B10: F09 | C10: 4 | D10: 91.7875 | E10: 367.15 | F10: =ROUND(C10*1000,0) -> 4000 | G10: =ROUND(D10*10000,0) -> 917875 | H10: =F10*G10/100000 -> 36715 | I10: =ROUND(H10,0) -> 36715 | J10: =I10/100 -> 367.15 | K10: =IF(OR(C10="",D10="",E10=""),"missing value",IF(ROUND(E10*100,0)=I10,"matches","MISMATCH")) -> matches | L10: EXCLUDED NOT_POSTED
A11: F0010 | B11: F10 | C11: 2 | D11: 416.075 | E11: 832.15 | F11: =ROUND(C11*1000,0) -> 2000 | G11: =ROUND(D11*10000,0) -> 4160750 | H11: =F11*G11/100000 -> 83215 | I11: =ROUND(H11,0) -> 83215 | J11: =I11/100 -> 832.15 | K11: =IF(OR(C11="",D11="",E11=""),"missing value",IF(ROUND(E11*100,0)=I11,"matches","MISMATCH")) -> matches | L11: EXCLUDED NOT_POSTED
A12: F0011 | B12: F11 | C12: 4 | D12: 96.508 | E12: 386.03 | F12: =ROUND(C12*1000,0) -> 4000 | G12: =ROUND(D12*10000,0) -> 965080 | H12: =F12*G12/100000 -> 38603.2 | I12: =ROUND(H12,0) -> 38603 | J12: =I12/100 -> 386.03 | K12: =IF(OR(C12="",D12="",E12=""),"missing value",IF(ROUND(E12*100,0)=I12,"matches","MISMATCH")) -> matches | L12: QUARANTINED UNEXPECTED_STATUS
A13: F0012 | B13: F12 | C13: 4 | D13: 91.7875 | E13: 367.15 | F13: =ROUND(C13*1000,0) -> 4000 | G13: =ROUND(D13*10000,0) -> 917875 | H13: =F13*G13/100000 -> 36715 | I13: =ROUND(H13,0) -> 36715 | J13: =I13/100 -> 367.15 | K13: =IF(OR(C13="",D13="",E13=""),"missing value",IF(ROUND(E13*100,0)=I13,"matches","MISMATCH")) -> matches | L13: QUARANTINED MISSING_REQUIRED_FIELD
A14: F0013 | B14: F13 | C14: 2 | D14: 91.7875 | E14: 183.58 | F14: =ROUND(C14*1000,0) -> 2000 | G14: =ROUND(D14*10000,0) -> 917875 | H14: =F14*G14/100000 -> 18357.5 | I14: =ROUND(H14,0) -> 18358 | J14: =I14/100 -> 183.58 | K14: =IF(OR(C14="",D14="",E14=""),"missing value",IF(ROUND(E14*100,0)=I14,"matches","MISMATCH")) -> matches | L14: QUARANTINED MISSING_REQUIRED_FIELD
A15: F0014 | B15: F14 | C15: 2 | D15: 416.075 | F15: =ROUND(C15*1000,0) -> 2000 | G15: =ROUND(D15*10000,0) -> 4160750 | H15: =F15*G15/100000 -> 83215 | I15: =ROUND(H15,0) -> 83215 | J15: =I15/100 -> 832.15 | K15: =IF(OR(C15="",D15="",E15=""),"missing value",IF(ROUND(E15*100,0)=I15,"matches","MISMATCH")) -> missing value | L15: QUARANTINED MISSING_REQUIRED_FIELD
A16: F0015 | B16: F15 | C16: 10 | D16: 0.465 | E16: 4.65 | F16: =ROUND(C16*1000,0) -> 10000 | G16: =ROUND(D16*10000,0) -> 4650 | H16: =F16*G16/100000 -> 465 | I16: =ROUND(H16,0) -> 465 | J16: =I16/100 -> 4.65 | K16: =IF(OR(C16="",D16="",E16=""),"missing value",IF(ROUND(E16*100,0)=I16,"matches","MISMATCH")) -> matches | L16: QUARANTINED MISSING_REQUIRED_FIELD
A17: F0016 | B17: F16 | C17: 4 | D17: 91.7875 | E17: 367.15 | F17: =ROUND(C17*1000,0) -> 4000 | G17: =ROUND(D17*10000,0) -> 917875 | H17: =F17*G17/100000 -> 36715 | I17: =ROUND(H17,0) -> 36715 | J17: =I17/100 -> 367.15 | K17: =IF(OR(C17="",D17="",E17=""),"missing value",IF(ROUND(E17*100,0)=I17,"matches","MISMATCH")) -> matches | L17: QUARANTINED MISSING_REQUIRED_FIELD
A18: F0017 | B18: F17 | C18: 2 | D18: 96.508 | E18: 193.02 | F18: =ROUND(C18*1000,0) -> 2000 | G18: =ROUND(D18*10000,0) -> 965080 | H18: =F18*G18/100000 -> 19301.6 | I18: =ROUND(H18,0) -> 19302 | J18: =I18/100 -> 193.02 | K18: =IF(OR(C18="",D18="",E18=""),"missing value",IF(ROUND(E18*100,0)=I18,"matches","MISMATCH")) -> matches | L18: ACCEPTED
A19: F0018 | B19: F18 | C19: 20 | D19: 0.465 | E19: 9.3 | F19: =ROUND(C19*1000,0) -> 20000 | G19: =ROUND(D19*10000,0) -> 4650 | H19: =F19*G19/100000 -> 930 | I19: =ROUND(H19,0) -> 930 | J19: =I19/100 -> 9.3 | K19: =IF(OR(C19="",D19="",E19=""),"missing value",IF(ROUND(E19*100,0)=I19,"matches","MISMATCH")) -> matches | L19: ACCEPTED
A20: F0019 | B20: F19 | C20: 4 | D20: 91.7875 | E20: 367.15 | F20: =ROUND(C20*1000,0) -> 4000 | G20: =ROUND(D20*10000,0) -> 917875 | H20: =F20*G20/100000 -> 36715 | I20: =ROUND(H20,0) -> 36715 | J20: =I20/100 -> 367.15 | K20: =IF(OR(C20="",D20="",E20=""),"missing value",IF(ROUND(E20*100,0)=I20,"matches","MISMATCH")) -> matches | L20: QUARANTINED CONFLICTING_DUPLICATE
A21: F0020 | B21: F20 | C21: 2 | D21: 430.76 | E21: 861.52 | F21: =ROUND(C21*1000,0) -> 2000 | G21: =ROUND(D21*10000,0) -> 4307600 | H21: =F21*G21/100000 -> 86152 | I21: =ROUND(H21,0) -> 86152 | J21: =I21/100 -> 861.52 | K21: =IF(OR(C21="",D21="",E21=""),"missing value",IF(ROUND(E21*100,0)=I21,"matches","MISMATCH")) -> matches | L21: QUARANTINED CONFLICTING_DUPLICATE
A22: F0021 | B22: F21 | C22: 2 | D22: 430.76 | E22: 861.52 | F22: =ROUND(C22*1000,0) -> 2000 | G22: =ROUND(D22*10000,0) -> 4307600 | H22: =F22*G22/100000 -> 86152 | I22: =ROUND(H22,0) -> 86152 | J22: =I22/100 -> 861.52 | K22: =IF(OR(C22="",D22="",E22=""),"missing value",IF(ROUND(E22*100,0)=I22,"matches","MISMATCH")) -> matches | L22: EXCLUDED NOT_POSTED
A23: F0022 | B23: F22 | C23: 4 | D23: 91.7875 | E23: 367.15 | F23: =ROUND(C23*1000,0) -> 4000 | G23: =ROUND(D23*10000,0) -> 917875 | H23: =F23*G23/100000 -> 36715 | I23: =ROUND(H23,0) -> 36715 | J23: =I23/100 -> 367.15 | K23: =IF(OR(C23="",D23="",E23=""),"missing value",IF(ROUND(E23*100,0)=I23,"matches","MISMATCH")) -> matches | L23: QUARANTINED UNKNOWN_CUSTOMER
A24: F0023 | B24: F23 | C24: 4 | D24: 91.7875 | E24: 367.15 | F24: =ROUND(C24*1000,0) -> 4000 | G24: =ROUND(D24*10000,0) -> 917875 | H24: =F24*G24/100000 -> 36715 | I24: =ROUND(H24,0) -> 36715 | J24: =I24/100 -> 367.15 | K24: =IF(OR(C24="",D24="",E24=""),"missing value",IF(ROUND(E24*100,0)=I24,"matches","MISMATCH")) -> matches | L24: QUARANTINED INVALID_DATE
A25: F0024 | B25: F24 | C25: 2 | D25: 416.075 | E25: 832.15 | F25: =ROUND(C25*1000,0) -> 2000 | G25: =ROUND(D25*10000,0) -> 4160750 | H25: =F25*G25/100000 -> 83215 | I25: =ROUND(H25,0) -> 83215 | J25: =I25/100 -> 832.15 | K25: =IF(OR(C25="",D25="",E25=""),"missing value",IF(ROUND(E25*100,0)=I25,"matches","MISMATCH")) -> matches | L25: QUARANTINED INVALID_DATE
A26: F0025 | B26: F25 | C26: 4 | D26: 96.508 | E26: 386.03 | F26: =ROUND(C26*1000,0) -> 4000 | G26: =ROUND(D26*10000,0) -> 965080 | H26: =F26*G26/100000 -> 38603.2 | I26: =ROUND(H26,0) -> 38603 | J26: =I26/100 -> 386.03 | K26: =IF(OR(C26="",D26="",E26=""),"missing value",IF(ROUND(E26*100,0)=I26,"matches","MISMATCH")) -> matches | L26: QUARANTINED INVALID_DATE
A27: F0026 | B27: F26 | C27: 2 | D27: 430.76 | E27: 861.52 | F27: =ROUND(C27*1000,0) -> 2000 | G27: =ROUND(D27*10000,0) -> 4307600 | H27: =F27*G27/100000 -> 86152 | I27: =ROUND(H27,0) -> 86152 | J27: =I27/100 -> 861.52 | K27: =IF(OR(C27="",D27="",E27=""),"missing value",IF(ROUND(E27*100,0)=I27,"matches","MISMATCH")) -> matches | L27: QUARANTINED UNKNOWN_CUSTOMER
... A57: F0056 | B57: F20 | C57: 2 | D57: 409.22 | E57: 818.44 | F57: =ROUND(C57*1000,0) -> 2000 | G57: =ROUND(D57*10000,0) -> 4092200 | H57: =F57*G57/100000 -> 81844 | I57: =ROUND(H57,0) -> 81844 | J57: =I57/100 -> 818.44 | K57: =IF(OR(C57="",D57="",E57=""),"missing value",IF(ROUND(E57*100,0)=I57,"matches","MISMATCH")) -> matches | L57: QUARANTINED CONFLICTING_DUPLICATE
A59: Rows | K59: =COUNTA(A2:A57) -> 56
A60: matches | K60: =COUNTIF(K2:K57,"matches") -> 51
A61: MISMATCH | K61: =COUNTIF(K2:K57,"MISMATCH") -> 4
A62: missing value | K62: =COUNTIF(K2:K57,"missing value") -> 1
A64: A row with MISMATCH is held by rule R7 only when no earlier rule decides: compare column K with column L. A credit keeps its sign: -2 x 91.79 is -183.58, so a delivered 183.58 does not match.

Sheet tax_and_gross
A1: RawRowID | B1: CaseID | C1: NetAmount | D1: TaxRate (empty: no tax applies) | E1: NetAmount in cents | F1: TaxRate in ten-thousandths | G1: Tax in cents, exact | H1: Tax in cents, rounded half up | I1: TaxAmount | J1: GrossAmount | K1: ExpectedTaxAmount (table) | L1: ExpectedGrossAmount (table) | M1: Calculation agrees with the table | N1: Tie | O1: TaxAmount with half-even rounding | P1: Half even differs
A2: F0001 | B2: F01 | C2: 367.15 | D2: 0.2 | E2: =ROUND(C2*100,0) -> 36715 | F2: =IF(D2="",0,ROUND(D2*10000,0)) -> 2000 | G2: =E2*F2/10000 -> 7343 | H2: =ROUND(G2,0) -> 7343 | I2: =H2/100 -> 73.43 | J2: =(E2+H2)/100 -> 440.58 | K2: 73.43 | L2: 440.58 | M2: =IF(AND(ROUND(I2*100,0)=ROUND(K2*100,0),ROUND(J2*100,0)=ROUND(L2*100,0)),"yes","NO") -> yes | N2: =IF(ABS(G2-TRUNC(G2))=0.5,"tie","") | O2: =IF(N2="tie",IF(MOD(ABS(TRUNC(G2)),2)=0,TRUNC(G2),TRUNC(G2)+SIGN(G2)),H2)/100 -> 73.43 | P2: =IF(ROUND(O2*100,0)=H2,"","differs")
A3: F0002 | B3: F02 | C3: 30.63 | D3: 0.2 | E3: =ROUND(C3*100,0) -> 3063 | F3: =IF(D3="",0,ROUND(D3*10000,0)) -> 2000 | G3: =E3*F3/10000 -> 612.6 | H3: =ROUND(G3,0) -> 613 | I3: =H3/100 -> 6.13 | J3: =(E3+H3)/100 -> 36.76 | K3: 6.13 | L3: 36.76 | M3: =IF(AND(ROUND(I3*100,0)=ROUND(K3*100,0),ROUND(J3*100,0)=ROUND(L3*100,0)),"yes","NO") -> yes | N3: =IF(ABS(G3-TRUNC(G3))=0.5,"tie","") | O3: =IF(N3="tie",IF(MOD(ABS(TRUNC(G3)),2)=0,TRUNC(G3),TRUNC(G3)+SIGN(G3)),H3)/100 -> 6.13 | P3: =IF(ROUND(O3*100,0)=H3,"","differs")
A4: F0003 | B4: F03 | C4: 793.04 | E4: =ROUND(C4*100,0) -> 79304 | F4: =IF(D4="",0,ROUND(D4*10000,0)) -> 0 | G4: =E4*F4/10000 -> 0 | H4: =ROUND(G4,0) -> 0 | I4: =H4/100 -> 0 | J4: =(E4+H4)/100 -> 793.04 | K4: 0 | L4: 793.04 | M4: =IF(AND(ROUND(I4*100,0)=ROUND(K4*100,0),ROUND(J4*100,0)=ROUND(L4*100,0)),"yes","NO") -> yes | N4: =IF(ABS(G4-TRUNC(G4))=0.5,"tie","") | O4: =IF(N4="tie",IF(MOD(ABS(TRUNC(G4)),2)=0,TRUNC(G4),TRUNC(G4)+SIGN(G4)),H4)/100 -> 0 | P4: =IF(ROUND(O4*100,0)=H4,"","differs")
A5: F0004 | B5: F04 | C5: 3 | D5: 0.055 | E5: =ROUND(C5*100,0) -> 300 | F5: =IF(D5="",0,ROUND(D5*10000,0)) -> 550 | G5: =E5*F5/10000 -> 16.5 | H5: =ROUND(G5,0) -> 17 | I5: =H5/100 -> 0.17 | J5: =(E5+H5)/100 -> 3.17 | K5: 0.17 | L5: 3.17 | M5: =IF(AND(ROUND(I5*100,0)=ROUND(K5*100,0),ROUND(J5*100,0)=ROUND(L5*100,0)),"yes","NO") -> yes | N5: =IF(ABS(G5-TRUNC(G5))=0.5,"tie","") -> tie | O5: =IF(N5="tie",IF(MOD(ABS(TRUNC(G5)),2)=0,TRUNC(G5),TRUNC(G5)+SIGN(G5)),H5)/100 -> 0.16 | P5: =IF(ROUND(O5*100,0)=H5,"","differs") -> differs
A6: F0005 | B6: F05 | C6: -367.15 | D6: 0.2 | E6: =ROUND(C6*100,0) -> -36715 | F6: =IF(D6="",0,ROUND(D6*10000,0)) -> 2000 | G6: =E6*F6/10000 -> -7343 | H6: =ROUND(G6,0) -> -7343 | I6: =H6/100 -> -73.43 | J6: =(E6+H6)/100 -> -440.58 | K6: -73.43 | L6: -440.58 | M6: =IF(AND(ROUND(I6*100,0)=ROUND(K6*100,0),ROUND(J6*100,0)=ROUND(L6*100,0)),"yes","NO") -> yes | N6: =IF(ABS(G6-TRUNC(G6))=0.5,"tie","") | O6: =IF(N6="tie",IF(MOD(ABS(TRUNC(G6)),2)=0,TRUNC(G6),TRUNC(G6)+SIGN(G6)),H6)/100 -> -73.43 | P6: =IF(ROUND(O6*100,0)=H6,"","differs")
A7: F0006 | B7: F06 | C7: -3 | D7: 0.055 | E7: =ROUND(C7*100,0) -> -300 | F7: =IF(D7="",0,ROUND(D7*10000,0)) -> 550 | G7: =E7*F7/10000 -> -16.5 | H7: =ROUND(G7,0) -> -17 | I7: =H7/100 -> -0.17 | J7: =(E7+H7)/100 -> -3.17 | K7: -0.17 | L7: -3.17 | M7: =IF(AND(ROUND(I7*100,0)=ROUND(K7*100,0),ROUND(J7*100,0)=ROUND(L7*100,0)),"yes","NO") -> yes | N7: =IF(ABS(G7-TRUNC(G7))=0.5,"tie","") -> tie | O7: =IF(N7="tie",IF(MOD(ABS(TRUNC(G7)),2)=0,TRUNC(G7),TRUNC(G7)+SIGN(G7)),H7)/100 -> -0.16 | P7: =IF(ROUND(O7*100,0)=H7,"","differs") -> differs
A8: F0007 | B8: F07 | C8: 2496.45 | D8: 0.19 | E8: =ROUND(C8*100,0) -> 249645 | F8: =IF(D8="",0,ROUND(D8*10000,0)) -> 1900 | G8: =E8*F8/10000 -> 47432.55 | H8: =ROUND(G8,0) -> 47433 | I8: =H8/100 -> 474.33 | J8: =(E8+H8)/100 -> 2970.78 | K8: 474.33 | L8: 2970.78 | M8: =IF(AND(ROUND(I8*100,0)=ROUND(K8*100,0),ROUND(J8*100,0)=ROUND(L8*100,0)),"yes","NO") -> yes | N8: =IF(ABS(G8-TRUNC(G8))=0.5,"tie","") | O8: =IF(N8="tie",IF(MOD(ABS(TRUNC(G8)),2)=0,TRUNC(G8),TRUNC(G8)+SIGN(G8)),H8)/100 -> 474.33 | P8: =IF(ROUND(O8*100,0)=H8,"","differs")
A9: F0008 | B9: F08 | C9: 0.5 | D9: 0.21 | E9: =ROUND(C9*100,0) -> 50 | F9: =IF(D9="",0,ROUND(D9*10000,0)) -> 2100 | G9: =E9*F9/10000 -> 10.5 | H9: =ROUND(G9,0) -> 11 | I9: =H9/100 -> 0.11 | J9: =(E9+H9)/100 -> 0.61 | K9: 0.11 | L9: 0.61 | M9: =IF(AND(ROUND(I9*100,0)=ROUND(K9*100,0),ROUND(J9*100,0)=ROUND(L9*100,0)),"yes","NO") -> yes | N9: =IF(ABS(G9-TRUNC(G9))=0.5,"tie","") -> tie | O9: =IF(N9="tie",IF(MOD(ABS(TRUNC(G9)),2)=0,TRUNC(G9),TRUNC(G9)+SIGN(G9)),H9)/100 -> 0.1 | P9: =IF(ROUND(O9*100,0)=H9,"","differs") -> differs
A10: F0017 | B10: F17 | C10: 193.02 | D10: 0.21 | E10: =ROUND(C10*100,0) -> 19302 | F10: =IF(D10="",0,ROUND(D10*10000,0)) -> 2100 | G10: =E10*F10/10000 -> 4053.42 | H10: =ROUND(G10,0) -> 4053 | I10: =H10/100 -> 40.53 | J10: =(E10+H10)/100 -> 233.55 | K10: 40.53 | L10: 233.55 | M10: =IF(AND(ROUND(I10*100,0)=ROUND(K10*100,0),ROUND(J10*100,0)=ROUND(L10*100,0)),"yes","NO") -> yes | N10: =IF(ABS(G10-TRUNC(G10))=0.5,"tie","") | O10: =IF(N10="tie",IF(MOD(ABS(TRUNC(G10)),2)=0,TRUNC(G10),TRUNC(G10)+SIGN(G10)),H10)/100 -> 40.53 | P10: =IF(ROUND(O10*100,0)=H10,"","differs")
A11: F0018 | B11: F18 | C11: 9.3 | D11: 0.19 | E11: =ROUND(C11*100,0) -> 930 | F11: =IF(D11="",0,ROUND(D11*10000,0)) -> 1900 | G11: =E11*F11/10000 -> 176.7 | H11: =ROUND(G11,0) -> 177 | I11: =H11/100 -> 1.77 | J11: =(E11+H11)/100 -> 11.07 | K11: 1.77 | L11: 11.07 | M11: =IF(AND(ROUND(I11*100,0)=ROUND(K11*100,0),ROUND(J11*100,0)=ROUND(L11*100,0)),"yes","NO") -> yes | N11: =IF(ABS(G11-TRUNC(G11))=0.5,"tie","") | O11: =IF(N11="tie",IF(MOD(ABS(TRUNC(G11)),2)=0,TRUNC(G11),TRUNC(G11)+SIGN(G11)),H11)/100 -> 1.77 | P11: =IF(ROUND(O11*100,0)=H11,"","differs")
A12: F0036 | B12: F36 | C12: 44.99 | E12: =ROUND(C12*100,0) -> 4499 | F12: =IF(D12="",0,ROUND(D12*10000,0)) -> 0 | G12: =E12*F12/10000 -> 0 | H12: =ROUND(G12,0) -> 0 | I12: =H12/100 -> 0 | J12: =(E12+H12)/100 -> 44.99 | K12: 0 | L12: 44.99 | M12: =IF(AND(ROUND(I12*100,0)=ROUND(K12*100,0),ROUND(J12*100,0)=ROUND(L12*100,0)),"yes","NO") -> yes | N12: =IF(ABS(G12-TRUNC(G12))=0.5,"tie","") | O12: =IF(N12="tie",IF(MOD(ABS(TRUNC(G12)),2)=0,TRUNC(G12),TRUNC(G12)+SIGN(G12)),H12)/100 -> 0 | P12: =IF(ROUND(O12*100,0)=H12,"","differs")
A13: F0037 | B13: F37 | C13: 183.58 | D13: 0.2 | E13: =ROUND(C13*100,0) -> 18358 | F13: =IF(D13="",0,ROUND(D13*10000,0)) -> 2000 | G13: =E13*F13/10000 -> 3671.6 | H13: =ROUND(G13,0) -> 3672 | I13: =H13/100 -> 36.72 | J13: =(E13+H13)/100 -> 220.3 | K13: 36.72 | L13: 220.3 | M13: =IF(AND(ROUND(I13*100,0)=ROUND(K13*100,0),ROUND(J13*100,0)=ROUND(L13*100,0)),"yes","NO") -> yes | N13: =IF(ABS(G13-TRUNC(G13))=0.5,"tie","") | O13: =IF(N13="tie",IF(MOD(ABS(TRUNC(G13)),2)=0,TRUNC(G13),TRUNC(G13)+SIGN(G13)),H13)/100 -> 36.72 | P13: =IF(ROUND(O13*100,0)=H13,"","differs")
A14: F0038 | B14: F38 | C14: 1764 | D14: 0.21 | E14: =ROUND(C14*100,0) -> 176400 | F14: =IF(D14="",0,ROUND(D14*10000,0)) -> 2100 | G14: =E14*F14/10000 -> 37044 | H14: =ROUND(G14,0) -> 37044 | I14: =H14/100 -> 370.44 | J14: =(E14+H14)/100 -> 2134.44 | K14: 370.44 | L14: 2134.44 | M14: =IF(AND(ROUND(I14*100,0)=ROUND(K14*100,0),ROUND(J14*100,0)=ROUND(L14*100,0)),"yes","NO") -> yes | N14: =IF(ABS(G14-TRUNC(G14))=0.5,"tie","") | O14: =IF(N14="tie",IF(MOD(ABS(TRUNC(G14)),2)=0,TRUNC(G14),TRUNC(G14)+SIGN(G14)),H14)/100 -> 370.44 | P14: =IF(ROUND(O14*100,0)=H14,"","differs")
A15: F0039 | B15: F39 | C15: 373.44 | D15: 0.2 | E15: =ROUND(C15*100,0) -> 37344 | F15: =IF(D15="",0,ROUND(D15*10000,0)) -> 2000 | G15: =E15*F15/10000 -> 7468.8 | H15: =ROUND(G15,0) -> 7469 | I15: =H15/100 -> 74.69 | J15: =(E15+H15)/100 -> 448.13 | K15: 74.69 | L15: 448.13 | M15: =IF(AND(ROUND(I15*100,0)=ROUND(K15*100,0),ROUND(J15*100,0)=ROUND(L15*100,0)),"yes","NO") -> yes | N15: =IF(ABS(G15-TRUNC(G15))=0.5,"tie","") | O15: =IF(N15="tie",IF(MOD(ABS(TRUNC(G15)),2)=0,TRUNC(G15),TRUNC(G15)+SIGN(G15)),H15)/100 -> 74.69 | P15: =IF(ROUND(O15*100,0)=H15,"","differs")
A16: F0040 | B16: F40 | C16: -832.15 | D16: 0.19 | E16: =ROUND(C16*100,0) -> -83215 | F16: =IF(D16="",0,ROUND(D16*10000,0)) -> 1900 | G16: =E16*F16/10000 -> -15810.85 | H16: =ROUND(G16,0) -> -15811 | I16: =H16/100 -> -158.11 | J16: =(E16+H16)/100 -> -990.26 | K16: -158.11 | L16: -990.26 | M16: =IF(AND(ROUND(I16*100,0)=ROUND(K16*100,0),ROUND(J16*100,0)=ROUND(L16*100,0)),"yes","NO") -> yes | N16: =IF(ABS(G16-TRUNC(G16))=0.5,"tie","") | O16: =IF(N16="tie",IF(MOD(ABS(TRUNC(G16)),2)=0,TRUNC(G16),TRUNC(G16)+SIGN(G16)),H16)/100 -> -158.11 | P16: =IF(ROUND(O16*100,0)=H16,"","differs")
A17: F0041 | B17: F41 | C17: -441 | D17: 0.21 | E17: =ROUND(C17*100,0) -> -44100 | F17: =IF(D17="",0,ROUND(D17*10000,0)) -> 2100 | G17: =E17*F17/10000 -> -9261 | H17: =ROUND(G17,0) -> -9261 | I17: =H17/100 -> -92.61 | J17: =(E17+H17)/100 -> -533.61 | K17: -92.61 | L17: -533.61 | M17: =IF(AND(ROUND(I17*100,0)=ROUND(K17*100,0),ROUND(J17*100,0)=ROUND(L17*100,0)),"yes","NO") -> yes | N17: =IF(ABS(G17-TRUNC(G17))=0.5,"tie","") | O17: =IF(N17="tie",IF(MOD(ABS(TRUNC(G17)),2)=0,TRUNC(G17),TRUNC(G17)+SIGN(G17)),H17)/100 -> -92.61 | P17: =IF(ROUND(O17*100,0)=H17,"","differs")
A18: F0043 | B18: F43 | C18: 2165.24 | D18: 0.2 | E18: =ROUND(C18*100,0) -> 216524 | F18: =IF(D18="",0,ROUND(D18*10000,0)) -> 2000 | G18: =E18*F18/10000 -> 43304.8 | H18: =ROUND(G18,0) -> 43305 | I18: =H18/100 -> 433.05 | J18: =(E18+H18)/100 -> 2598.29 | K18: 433.05 | L18: 2598.29 | M18: =IF(AND(ROUND(I18*100,0)=ROUND(K18*100,0),ROUND(J18*100,0)=ROUND(L18*100,0)),"yes","NO") -> yes | N18: =IF(ABS(G18-TRUNC(G18))=0.5,"tie","") | O18: =IF(N18="tie",IF(MOD(ABS(TRUNC(G18)),2)=0,TRUNC(G18),TRUNC(G18)+SIGN(G18)),H18)/100 -> 433.05 | P18: =IF(ROUND(O18*100,0)=H18,"","differs")
A19: F0044 | B19: F44 | C19: 36.75 | D19: 0.05 | E19: =ROUND(C19*100,0) -> 3675 | F19: =IF(D19="",0,ROUND(D19*10000,0)) -> 500 | G19: =E19*F19/10000 -> 183.75 | H19: =ROUND(G19,0) -> 184 | I19: =H19/100 -> 1.84 | J19: =(E19+H19)/100 -> 38.59 | K19: 1.84 | L19: 38.59 | M19: =IF(AND(ROUND(I19*100,0)=ROUND(K19*100,0),ROUND(J19*100,0)=ROUND(L19*100,0)),"yes","NO") -> yes | N19: =IF(ABS(G19-TRUNC(G19))=0.5,"tie","") | O19: =IF(N19="tie",IF(MOD(ABS(TRUNC(G19)),2)=0,TRUNC(G19),TRUNC(G19)+SIGN(G19)),H19)/100 -> 1.84 | P19: =IF(ROUND(O19*100,0)=H19,"","differs")
A20: F0045 | B20: F45 | C20: 4510.7 | D20: 0 | E20: =ROUND(C20*100,0) -> 451070 | F20: =IF(D20="",0,ROUND(D20*10000,0)) -> 0 | G20: =E20*F20/10000 -> 0 | H20: =ROUND(G20,0) -> 0 | I20: =H20/100 -> 0 | J20: =(E20+H20)/100 -> 4510.7 | K20: 0 | L20: 4510.7 | M20: =IF(AND(ROUND(I20*100,0)=ROUND(K20*100,0),ROUND(J20*100,0)=ROUND(L20*100,0)),"yes","NO") -> yes | N20: =IF(ABS(G20-TRUNC(G20))=0.5,"tie","") | O20: =IF(N20="tie",IF(MOD(ABS(TRUNC(G20)),2)=0,TRUNC(G20),TRUNC(G20)+SIGN(G20)),H20)/100 -> 0 | P20: =IF(ROUND(O20*100,0)=H20,"","differs")
A21: F0046 | B21: F46 | C21: 81822 | D21: 0.22 | E21: =ROUND(C21*100,0) -> 8182200 | F21: =IF(D21="",0,ROUND(D21*10000,0)) -> 2200 | G21: =E21*F21/10000 -> 1800084 | H21: =ROUND(G21,0) -> 1800084 | I21: =H21/100 -> 18000.84 | J21: =(E21+H21)/100 -> 99822.84 | K21: 18000.84 | L21: 99822.84 | M21: =IF(AND(ROUND(I21*100,0)=ROUND(K21*100,0),ROUND(J21*100,0)=ROUND(L21*100,0)),"yes","NO") -> yes | N21: =IF(ABS(G21-TRUNC(G21))=0.5,"tie","") | O21: =IF(N21="tie",IF(MOD(ABS(TRUNC(G21)),2)=0,TRUNC(G21),TRUNC(G21)+SIGN(G21)),H21)/100 -> 18000.84 | P21: =IF(ROUND(O21*100,0)=H21,"","differs")
A22: F0047 | B22: F47 | C22: 9.99 | E22: =ROUND(C22*100,0) -> 999 | F22: =IF(D22="",0,ROUND(D22*10000,0)) -> 0 | G22: =E22*F22/10000 -> 0 | H22: =ROUND(G22,0) -> 0 | I22: =H22/100 -> 0 | J22: =(E22+H22)/100 -> 9.99 | K22: 0 | L22: 9.99 | M22: =IF(AND(ROUND(I22*100,0)=ROUND(K22*100,0),ROUND(J22*100,0)=ROUND(L22*100,0)),"yes","NO") -> yes | N22: =IF(ABS(G22-TRUNC(G22))=0.5,"tie","") | O22: =IF(N22="tie",IF(MOD(ABS(TRUNC(G22)),2)=0,TRUNC(G22),TRUNC(G22)+SIGN(G22)),H22)/100 -> 0 | P22: =IF(ROUND(O22*100,0)=H22,"","differs")
A23: F0054 | B23: F21 | C23: 861.52 | D23: 0.2 | E23: =ROUND(C23*100,0) -> 86152 | F23: =IF(D23="",0,ROUND(D23*10000,0)) -> 2000 | G23: =E23*F23/10000 -> 17230.4 | H23: =ROUND(G23,0) -> 17230 | I23: =H23/100 -> 172.3 | J23: =(E23+H23)/100 -> 1033.82 | K23: 172.3 | L23: 1033.82 | M23: =IF(AND(ROUND(I23*100,0)=ROUND(K23*100,0),ROUND(J23*100,0)=ROUND(L23*100,0)),"yes","NO") -> yes | N23: =IF(ABS(G23-TRUNC(G23))=0.5,"tie","") | O23: =IF(N23="tie",IF(MOD(ABS(TRUNC(G23)),2)=0,TRUNC(G23),TRUNC(G23)+SIGN(G23)),H23)/100 -> 172.3 | P23: =IF(ROUND(O23*100,0)=H23,"","differs")
A25: Lines | M25: =COUNTA(A2:A23) -> 22
A26: Agree | M26: =COUNTIF(M2:M23,"yes") -> 22
A27: Ties | M27: =COUNTIF(N2:N23,"tie") -> 3
A28: Half even differs | M28: =COUNTIF(P2:P23,"differs") -> 3
A30: These are the 22 fixture lines that contract 1.0 accepts. A tie is a tax that ends exactly on half a cent. Only on a tie do half up and half even give different results: a test without a tie cannot tell them apart.

Sheet customers
A1: CustomerID | B1: CustomerName | C1: Segment | D1: Country | E1: Region | F1: City | G1: PostalCode | H1: BillingCurrency | I1: PaymentTerms | J1: CreditLimit | K1: AccountManager | L1: ParentCustomerID | M1: IsActive | N1: CreatedDate | O1: LastUpdated | P1: Rows with this CustomerID
A2: C200001 | B2: Alder Ridge Tyre Centre SARL | C2: DEALER | D2: FR | E2: EMEA | F2: Lyon | G2: 69003 | H2: EUR | I2: NET30 | J2: 40000 | K2: AM-101 | M2: true | N2: 2019-03-14 | O2: 2025-03-11 09:30:00 | P2: =COUNTIF($A$2:$A$12,A2) -> 1
A3: C200002 | B3: Basalt Vale Logistics GmbH | C3: FLEET | D3: DE | E3: EMEA | F3: Kassel | G3: 34117 | H3: EUR | I3: NET45 | J3: 250000 | K3: AM-102 | M3: true | N3: 2019-03-14 | O3: 2025-03-11 09:30:00 | P3: =COUNTIF($A$2:$A$12,A3) -> 1
A4: C200003 | B4: Cinder Forge Distribution Ltd | C4: DISTRIBUTOR | D4: GB | E4: EMEA | F4: Leeds | G4: LS1 4AB | H4: GBP | I4: NET60 | J4: 600000 | K4: AM-103 | M4: true | N4: 2019-03-14 | O4: 2025-03-11 09:30:00 | P4: =COUNTIF($A$2:$A$12,A4) -> 1
A5: C200004 | B5: Dorsal Haven Online Inc | C5: ECOMMERCE | D5: US | E5: AMER | F5: Dayton | G5: 45402 | H5: USD | I5: PREPAID | J5: 90000 | K5: AM-104 | M5: true | N5: 2019-03-14 | O5: 2025-03-11 09:30:00 | P5: =COUNTIF($A$2:$A$12,A5) -> 1
A6: C200005 | B6: Ember Cross Vehicles SPA | C6: OEM | D6: IT | E6: EMEA | F6: Bologna | G6: 40121 | H6: EUR | I6: NET60 | J6: 2000000 | K6: AM-105 | M6: true | N6: 2019-03-14 | O6: 2025-03-11 09:30:00 | P6: =COUNTIF($A$2:$A$12,A6) -> 1
A7: C200006 | B7: Fallow Field Autoservice SL | C7: DEALER | D7: ES | E7: EMEA | F7: Vigo | G7: 36201 | H7: EUR | I7: NET30 | J7: 35000 | K7: AM-101 | M7: true | N7: 2019-03-14 | O7: 2025-03-11 09:30:00 | P7: =COUNTIF($A$2:$A$12,A7) -> 1
A8: C200007 | B8: Garnet Gate Transport BV | C8: FLEET | D8: NL | E8: EMEA | F8: Utrecht | G8: 3511 AB | H8: EUR | I8: NET45 | J8: 180000 | K8: AM-106 | M8: true | N8: 2019-03-14 | O8: 2025-03-11 09:30:00 | P8: =COUNTIF($A$2:$A$12,A8) -> 2
A9: C200007 | B9: Garnet Gate Transport BV | C9: DISTRIBUTOR | D9: NL | E9: EMEA | F9: Breda | G9: 4811 EF | H9: EUR | I9: NET45 | J9: 185000 | K9: AM-106 | M9: true | N9: 2019-03-14 | O9: 2026-01-20 14:05:00 | P9: =COUNTIF($A$2:$A$12,A9) -> 2
A10: C200008 | B10: Harrow Mill Wheel Works Inc | C10: DEALER | D10: CA | E10: AMER | F10: Halifax | G10: B3H 1A1 | H10: CAD | I10: NET30 | J10: 55000 | K10: AM-107 | M10: true | N10: 2019-03-14 | O10: 2025-03-11 09:30:00 | P10: =COUNTIF($A$2:$A$12,A10) -> 1
A11: C200009 | B11: Ingot Point Trade Supply Sp. z o.o. | C11: DISTRIBUTOR | D11: PL | E11: EMEA | F11: Lodz | G11: 90-001 | H11: PLN | I11: NET45 | J11: 700000 | K11: AM-108 | M11: true | N11: 2019-03-14 | O11: 2025-03-11 09:30:00 | P11: =COUNTIF($A$2:$A$12,A11) -> 1
A12: C200010 | B12: Juniper Quay Fleet Services SAS | C12: FLEET | D12: FR | E12: EMEA | F12: Nantes | G12: 44000 | H12: EUR | I12: NET45 | J12: 120000 | K12: AM-102 | L12: C200001 | M12: true | N12: 2019-03-14 | O12: 2025-03-11 09:30:00 | P12: =COUNTIF($A$2:$A$12,A12) -> 1
A14: Keys with more than one row | P14: =SUMPRODUCT((P2:P12>1)/P2:P12) -> 1
A16: The table has no enforced key. A key with more than one row is the reason for the AMBIGUOUS reason codes.

Sheet products
A1: ProductID | B1: ProductName | C1: ProductLine | D1: ProductFamily | E1: SizeDesignation | F1: RimDiameterInch | G1: UnitOfMeasure | H1: ListPrice | I1: ListPriceCurrency | J1: TaxClass | K1: Status | L1: WeightKg | M1: LaunchDate | N1: LastUpdated | O1: Rows with this ProductID
A2: P-20001 | B2: Passenger Summer 205/55 R16 91V | C2: PASSENGER | D2: SUMMER | E2: 205/55 R16 91V | F2: 16 | G2: EA | H2: 104.9 | I2: EUR | J2: STANDARD | K2: ACTIVE | L2: 8.9 | M2: 2021-02-01 | N2: 2025-03-11 09:30:00 | O2: =COUNTIF($A$2:$A$10,A2) -> 1
A3: P-20002 | B3: Truck Regional 315/70 R22.5 156L | C3: TRUCK_BUS | D3: REGIONAL | E3: 315/70 R22.5 156L | F3: 22.5 | G3: EA | H3: 489.5 | I3: EUR | J3: STANDARD | K3: ACTIVE | L3: 62.4 | M3: 2021-02-01 | N3: 2025-03-11 09:30:00 | O3: =COUNTIF($A$2:$A$10,A3) -> 1
A4: P-20003 | B4: Fitting Plus 2 | C4: SERVICES | D4: FITTING | G4: HR | H4: 12.25 | I4: EUR | J4: STANDARD | K4: ACTIVE | M4: 2021-02-01 | N4: 2025-03-11 09:30:00 | O4: =COUNTIF($A$2:$A$10,A4) -> 1
A5: P-20004 | B5: Seasonal Storage Basic 1 | C5: SERVICES | D5: STORAGE | G5: EA | H5: 3 | I5: EUR | J5: REDUCED | K5: ACTIVE | M5: 2021-02-01 | N5: 2025-03-11 09:30:00 | O5: =COUNTIF($A$2:$A$10,A5) -> 1
A6: P-20005 | B6: Valve Kit Standard 12 | C6: ACCESSORIES | D6: VALVES | G6: EA | H6: 0.5 | I6: EUR | J6: STANDARD | K6: ACTIVE | M6: 2021-02-01 | N6: 2025-03-11 09:30:00 | O6: =COUNTIF($A$2:$A$10,A6) -> 1
A7: P-20006 | B7: Moto Sport 120/70 ZR17 | C7: TWO_WHEEL | D7: SPORT | E7: 120/70 ZR17 | F7: 17 | G7: EA | H7: 139 | I7: EUR | J7: STANDARD | K7: ACTIVE | L7: 4.3 | M7: 2021-02-01 | N7: 2025-03-11 09:30:00 | O7: =COUNTIF($A$2:$A$10,A7) -> 2
A8: P-20006 | B8: Moto Sport 120/70 ZR17 | C8: TWO_WHEEL | D8: SPORT | E8: 120/70 ZR17 | F8: 17 | G8: EA | H8: 144.56 | I8: EUR | J8: STANDARD | K8: PHASE_OUT | L8: 4.3 | M8: 2021-02-01 | N8: 2026-01-20 14:05:00 | O8: =COUNTIF($A$2:$A$10,A8) -> 2
A9: P-20007 | B9: Agri Tractor Radial 480/70 R34 149D | C9: AGRICULTURAL | D9: TRACTOR | E9: 480/70 R34 149D | F9: 34 | G9: EA | H9: 1258.86 | I9: EUR | J9: STANDARD | K9: ACTIVE | L9: 92.5 | M9: 2021-02-01 | N9: 2025-03-11 09:30:00 | O9: =COUNTIF($A$2:$A$10,A9) -> 1
A10: P-20008 | B10: Fleet Inspection On Site 4 | C10: SERVICES | D10: INSPECTION | G10: HR | H10: 29.99 | I10: EUR | J10: EXEMPT | K10: ACTIVE | M10: 2021-02-01 | N10: 2025-03-11 09:30:00 | O10: =COUNTIF($A$2:$A$10,A10) -> 1
A12: Keys with more than one row | O12: =SUMPRODUCT((O2:O10>1)/O2:O10) -> 1
A14: The table has no enforced key. A key with more than one row is the reason for the AMBIGUOUS reason codes.

Sheet orders
A1: OrderID | B1: OrderLineNumber | C1: OrderDate | D1: CustomerID | E1: ProductID | F1: OrderedQuantity | G1: AgreedUnitPrice | H1: Currency | I1: OrderStatus | J1: SalesChannel | K1: SalesOrg | L1: RequestedDeliveryDate | M1: LastUpdated | N1: Rows with this OrderID and OrderLineNumber
A2: SO-3000001 | B2: 1 | C2: 2026-03-24 | D2: C200001 | E2: P-20001 | F2: 4 | G2: 91.7875 | H2: EUR | I2: INVOICED | J2: PORTAL | K2: FR10 | L2: 2026-03-31 | M2: 2026-03-24 10:15:00 | N2: =COUNTIFS($A$2:$A$43,A2,$B$2:$B$43,B2) -> 1
A3: SO-3000001 | B3: 2 | C3: 2026-03-24 | D3: C200001 | E3: P-20003 | F3: 2.5 | G3: 12.25 | H3: EUR | I3: INVOICED | J3: PORTAL | K3: FR10 | L3: 2026-03-31 | M3: 2026-03-24 10:15:00 | N3: =COUNTIFS($A$2:$A$43,A3,$B$2:$B$43,B3) -> 1
A4: SO-3000002 | B4: 1 | C4: 2026-03-24 | D4: C200004 | E4: P-20001 | F4: 8 | G4: 99.1305 | H4: USD | I4: INVOICED | J4: PORTAL | K4: US10 | L4: 2026-03-31 | M4: 2026-03-24 10:15:00 | N4: =COUNTIFS($A$2:$A$43,A4,$B$2:$B$43,B4) -> 1
A5: SO-3000003 | B5: 1 | C5: 2026-03-24 | D5: C200010 | E5: P-20004 | F5: 1 | G5: 3 | H5: EUR | I5: INVOICED | J5: PORTAL | K5: FR10 | L5: 2026-03-31 | M5: 2026-03-24 10:15:00 | N5: =COUNTIFS($A$2:$A$43,A5,$B$2:$B$43,B5) -> 1
A6: SO-3000004 | B6: 1 | C6: 2026-03-24 | D6: C200002 | E6: P-20002 | F6: 6 | G6: 416.075 | H6: EUR | I6: INVOICED | J6: PORTAL | K6: DE10 | L6: 2026-03-31 | M6: 2026-03-24 10:15:00 | N6: =COUNTIFS($A$2:$A$43,A6,$B$2:$B$43,B6) -> 1
A7: SO-3000005 | B7: 1 | C7: 2026-03-24 | D7: C200006 | E7: P-20005 | F7: 1 | G7: 0.5 | H7: EUR | I7: INVOICED | J7: PORTAL | K7: ES10 | L7: 2026-03-31 | M7: 2026-03-24 10:15:00 | N7: =COUNTIFS($A$2:$A$43,A7,$B$2:$B$43,B7) -> 1
A8: SO-3000006 | B8: 1 | C8: 2026-03-24 | D8: C200001 | E8: P-20001 | F8: 4 | G8: 91.7875 | H8: EUR | I8: INVOICED | J8: PORTAL | K8: FR10 | L8: 2026-03-31 | M8: 2026-03-24 10:15:00 | N8: =COUNTIFS($A$2:$A$43,A8,$B$2:$B$43,B8) -> 1
A9: SO-3000006 | B9: 2 | C9: 2026-03-24 | D9: C200002 | E9: P-20002 | F9: 2 | G9: 416.075 | H9: EUR | I9: INVOICED | J9: PORTAL | K9: DE10 | L9: 2026-03-31 | M9: 2026-03-24 10:15:00 | N9: =COUNTIFS($A$2:$A$43,A9,$B$2:$B$43,B9) -> 1
A10: SO-3000006 | B10: 3 | C10: 2026-03-24 | D10: C200006 | E10: P-20001 | F10: 4 | G10: 96.508 | H10: EUR | I10: INVOICED | J10: PORTAL | K10: ES10 | L10: 2026-03-31 | M10: 2026-03-24 10:15:00 | N10: =COUNTIFS($A$2:$A$43,A10,$B$2:$B$43,B10) -> 1
A11: SO-3000007 | B11: 1 | C11: 2026-03-24 | D11: C200001 | E11: P-20001 | F11: 4 | G11: 91.7875 | H11: EUR | I11: INVOICED | J11: PORTAL | K11: FR10 | L11: 2026-03-31 | M11: 2026-03-24 10:15:00 | N11: =COUNTIFS($A$2:$A$43,A11,$B$2:$B$43,B11) -> 1
A12: SO-3000007 | B12: 2 | C12: 2026-03-24 | D12: C200001 | E12: P-20001 | F12: 2 | G12: 91.7875 | H12: EUR | I12: INVOICED | J12: PORTAL | K12: FR10 | L12: 2026-03-31 | M12: 2026-03-24 10:15:00 | N12: =COUNTIFS($A$2:$A$43,A12,$B$2:$B$43,B12) -> 1
A13: SO-3000007 | B13: 3 | C13: 2026-03-24 | D13: C200002 | E13: P-20002 | F13: 2 | G13: 416.075 | H13: EUR | I13: INVOICED | J13: PORTAL | K13: DE10 | L13: 2026-03-31 | M13: 2026-03-24 10:15:00 | N13: =COUNTIFS($A$2:$A$43,A13,$B$2:$B$43,B13) -> 1
... A43: SO-3000019 | B43: 3 | C43: 2026-03-30 | D43: C200002 | E43: P-20002 | F43: 4 | G43: 416.075 | H43: EUR | I43: CONFIRMED | J43: EDI | K43: DE10 | L43: 2026-04-09 | M43: 2026-03-30 08:05:00 | N43: =COUNTIFS($A$2:$A$43,A43,$B$2:$B$43,B43) -> 1
A45: Keys with more than one row | N45: =SUMPRODUCT((N2:N43>1)/N2:N43) -> 1
A47: The table has no enforced key. A key with more than one row is the reason for the AMBIGUOUS reason codes.

Sheet expected_results
A1: RawRowID | B1: ContractVersion | C1: CaseID | D1: ExpectedDisposition | E1: ExpectedReason
A2: F0001 | B2: 1.0 | C2: F01 | D2: ACCEPTED
A3: F0002 | B3: 1.0 | C3: F02 | D3: ACCEPTED
A4: F0003 | B4: 1.0 | C4: F03 | D4: ACCEPTED
A5: F0004 | B5: 1.0 | C5: F04 | D5: ACCEPTED
A6: F0005 | B6: 1.0 | C6: F05 | D6: ACCEPTED
A7: F0006 | B7: 1.0 | C7: F06 | D7: ACCEPTED
A8: F0007 | B8: 1.0 | C8: F07 | D8: ACCEPTED
A9: F0008 | B9: 1.0 | C9: F08 | D9: ACCEPTED
A10: F0009 | B10: 1.0 | C10: F09 | D10: EXCLUDED | E10: NOT_POSTED
A11: F0010 | B11: 1.0 | C11: F10 | D11: EXCLUDED | E11: NOT_POSTED
A12: F0011 | B12: 1.0 | C12: F11 | D12: QUARANTINED | E12: UNEXPECTED_STATUS
A13: F0012 | B13: 1.0 | C13: F12 | D13: QUARANTINED | E13: MISSING_REQUIRED_FIELD
A14: F0013 | B14: 1.0 | C14: F13 | D14: QUARANTINED | E14: MISSING_REQUIRED_FIELD
A15: F0014 | B15: 1.0 | C15: F14 | D15: QUARANTINED | E15: MISSING_REQUIRED_FIELD
A16: F0015 | B16: 1.0 | C16: F15 | D16: QUARANTINED | E16: MISSING_REQUIRED_FIELD
A17: F0016 | B17: 1.0 | C17: F16 | D17: QUARANTINED | E17: MISSING_REQUIRED_FIELD
A18: F0017 | B18: 1.0 | C18: F17 | D18: ACCEPTED
A19: F0018 | B19: 1.0 | C19: F18 | D19: ACCEPTED
A20: F0019 | B20: 1.0 | C20: F19 | D20: QUARANTINED | E20: CONFLICTING_DUPLICATE
A21: F0020 | B21: 1.0 | C21: F20 | D21: QUARANTINED | E21: CONFLICTING_DUPLICATE
A22: F0021 | B22: 1.0 | C22: F21 | D22: EXCLUDED | E22: NOT_POSTED
A23: F0022 | B23: 1.0 | C23: F22 | D23: QUARANTINED | E23: UNKNOWN_CUSTOMER
A24: F0023 | B24: 1.0 | C24: F23 | D24: QUARANTINED | E24: INVALID_DATE
A25: F0024 | B25: 1.0 | C25: F24 | D25: QUARANTINED | E25: INVALID_DATE
A26: F0025 | B26: 1.0 | C26: F25 | D26: QUARANTINED | E26: INVALID_DATE
A27: F0026 | B27: 1.0 | C27: F26 | D27: QUARANTINED | E27: UNKNOWN_CUSTOMER
A28: F0027 | B28: 1.0 | C28: F27 | D28: QUARANTINED | E28: AMBIGUOUS_CUSTOMER
A29: F0028 | B29: 1.0 | C29: F28 | D29: QUARANTINED | E29: UNKNOWN_CUSTOMER
A30: F0029 | B30: 1.0 | C30: F29 | D30: QUARANTINED | E30: UNKNOWN_PRODUCT
A31: F0030 | B31: 1.0 | C31: F30 | D31: QUARANTINED | E31: AMBIGUOUS_PRODUCT
... A36: F0035 | B36: 1.0 | C36: F35 | D36: QUARANTINED | E36: UNKNOWN_PRODUCT
A37: F0036 | B37: 1.0 | C37: F36 | D37: ACCEPTED
A38: F0037 | B38: 1.0 | C38: F37 | D38: ACCEPTED
A39: F0038 | B39: 1.0 | C39: F38 | D39: ACCEPTED
A40: F0039 | B40: 1.0 | C40: F39 | D40: ACCEPTED
A41: F0040 | B41: 1.0 | C41: F40 | D41: ACCEPTED
A42: F0041 | B42: 1.0 | C42: F41 | D42: ACCEPTED
A43: F0042 | B43: 1.0 | C43: F42 | D43: QUARANTINED | E43: AMOUNT_MISMATCH
A44: F0043 | B44: 1.0 | C44: F43 | D44: ACCEPTED
...
